Workbook
Name applicantname: #REF!
Name applicantname: #REF!
Name applicantname: #REF!
Name applicantname: #REF!
Name applicantname: #REF!
Name applicantname: #REF!
Name Beg_Bal: #REF!
Name Beg_Bal: #REF!
Name Beg_Bal: #REF!
Name Beg_Bal: #REF!
Name Beg_Bal: #REF!
Name Beg_Bal: #REF!
Name Beg_Bal: #REF!
Name biztype: [1]Sheet1!$BO$2:$BO$5
Name borrowers: [1]Sheet1!$BQ$11:$BQ$20
Name Case1: [1]Sheet1!$E$3:$E$30
Name Case10: [1]Sheet1!$N$3:$N$30
Name Case2: [1]Sheet1!$F$3:$F$30
Name Case3: [1]Sheet1!$G$3:$G$30
Name Case4: [1]Sheet1!$H$3:$H$30
Name Case5: [1]Sheet1!$I$3:$I$30
Name Case6: [1]Sheet1!$J$3:$J$30
Name Case7: [1]Sheet1!$K$3:$K$30
Name Case8: [1]Sheet1!$L$3:$L$30
Name Case9: [1]Sheet1!$M$3:$M$30
Name Data: #REF!
Name Data: #REF!
Name Data: #REF!
Name Data: #REF!
Name Data: #REF!
Name Data: #REF!
Name Data: #REF!
Name End_Bal: #REF!
Name End_Bal: #REF!
Name End_Bal: #REF!
Name End_Bal: #REF!
Name End_Bal: #REF!
Name End_Bal: #REF!
Name End_Bal: #REF!
Name entity_type: [1]Sheet1!$AZ$2:$AZ$19
Name Extra_Pay: #REF!
Name Extra_Pay: #REF!
Name Extra_Pay: #REF!
Name Extra_Pay: #REF!
Name Extra_Pay: #REF!
Name Extra_Pay: #REF!
Name Extra_Pay: #REF!
Name financials: [2]Workings!$N$4:$N$7
Name Full_Print: #REF!
Name Full_Print: #REF!
Name Full_Print: #REF!
Name Full_Print: #REF!
Name Full_Print: #REF!
Name Full_Print: #REF!
Name Full_Print: #REF!
Name Header_Row: ROW(#REF!)
Name Header_Row: ROW(#REF!)
Name Header_Row: ROW(#REF!)
Name Header_Row: ROW(#REF!)
Name Header_Row: ROW(#REF!)

Sheet Product type
A1: PRODUCT & SCHEME CODE MASTER
A2: Product Hierarchy — Scheme Code, Category, Sub-Category & LTV/FOIR Deviation Norms
A4: S.No | B4: Product | C4: Scheme Code | D4: Category | E4: Sub-Category / Loan Type | F4: Applicable To | G4: LTV Norm | H4: Actual LTV (%) | I4: Deviation Status
A5: 1 | B5: Personal Loan | C5: General Personal Loan | D5: - | E5: - | F5: Salaried | G5: 60% | I5: =IF(H5="","-",IF(H5>0,"Deviation","Within Norms")) -> -
A6: 2 | B6: Personal Loan | C6: General Personal Loan | D6: - | E6: - | F6: Self Employed | G6: 60% | I6: =IF(H6="","-",IF(H6>60,"Deviation","Within Norms")) -> -
A7: 3 | B7: Personal Loan | C7: Group Employee Personal Loan | D7: - | E7: - | F7: Salaried | G7: 60% | I7: =IF(H7="","-",IF(H7>60,"Deviation","Within Norms")) -> -
A8: 4 | B8: Personal Loan | C8: Group Employee Personal Loan | D8: - | E8: - | F8: Self Employed | G8: 60% | I8: =IF(H8="","-",IF(H8>60,"Deviation","Within Norms")) -> -
A9: 5 | B9: Business Loan | C9: General Business Loan | D9: - | E9: - | F9: Salaried | G9: 60% | I9: =IF(H9="","-",IF(H9>60,"Deviation","Within Norms")) -> -
A10: 6 | B10: Business Loan | C10: General Business Loan | D10: - | E10: - | F10: Self Employed | G10: 60% | I10: =IF(H10="","-",IF(H10>60,"Deviation","Within Norms")) -> -
A11: 7 | B11: Business Loan | C11: Group Employee Business Loan | D11: - | E11: - | F11: Salaried | G11: 60% | I11: =IF(H11="","-",IF(H11>60,"Deviation","Within Norms")) -> -
A12: 8 | B12: Business Loan | C12: Group Employee Business Loan | D12: - | E12: - | F12: Self Employed | G12: 60% | I12: =IF(H12="","-",IF(H12>60,"Deviation","Within Norms")) -> -
A13: 9 | B13: Micro Loan | C13: - | D13: - | E13: - | F13: Self Employed | G13: 60% | I13: =IF(H13="","-",IF(H13>60,"Deviation","Within Norms")) -> -
A14: 10 | B14: Home Loan | C14: Small Ticket Home Loan | D14: Salaried | E14: Construction Loan / Composite Loan / Purchase of Property | F14: Salaried | G14: 60% | I14: =IF(H14="","-",IF(H14>60,"Deviation","Within Norms")) -> -
A15: 11 | B15: Home Loan | C15: Small Ticket Home Loan | D15: Self Employed | E15: Construction Loan / Composite Loan / Purchase of Property | F15: Self Employed | G15: 60% | I15: =IF(H15="","-",IF(H15>60,"Deviation","Within Norms")) -> -
A16: 12 | B16: Home Loan | C16: High Ticket Home Loan | D16: Salaried | E16: Construction Loan / Composite Loan / Purchase of Property | F16: Salaried | G16: 60% | I16: =IF(H16="","-",IF(H16>60,"Deviation","Within Norms")) -> -
A17: 13 | B17: Home Loan | C17: High Ticket Home Loan | D17: Self Employed | E17: Construction Loan / Composite Loan / Purchase of Property | F17: Self Employed | G17: 60% | I17: =IF(H17="","-",IF(H17>60,"Deviation","Within Norms")) -> -
A18: 14 | B18: LAP Loan | C18: Small Ticket LAP | D18: Self Employed | F18: Salaried / Self Employed | G18: 60% | I18: =IF(H18="","-",IF(H18>60,"Deviation","Within Norms")) -> -
A19: 15 | B19: LAP Loan | C19: High Ticket LAP | D19: Self Employed | F19: Salaried / Self Employed | G19: 60% | I19: =IF(H19="","-",IF(H19>60,"Deviation","Within Norms")) -> -
A21: Notes: 1. LTV Norm of 60% applies only to secured products — Home Loan (Small Ticket / High Ticket) and LAP (Small Ticket / High Ticket). Personal Loan, Business Loan, and Micro Loan are unsecured / income-based products and are marked Not Applicable (N/A). 2. Enter the case's Actual LTV (%) in column H — the Deviation Status in column I updates automatically: 'Within Norms' if LTV ≤ 60%, 'Deviation' if LTV exceeds 60% (flat/property cases beyond the 60% threshold must be routed through the deviation approval process). 3. Home Loan sub-categories cover Construction Loan, Composite Loan, and Purchase of Property, applicable to both Salaried and Self Employed borrowers under each ticket size.

Sheet Key loan summary 
B1: Version -1 | L1: SMART SUMMARY DASHBOARD — UNDERWRITER VIEW
B2: Sourcing and Key loan terms: | L2: Auto-calculated from linked sheets (RTR, Banking, Collateral, Eligibility, Deviation List). Verify source inputs before relying on any figure below. | XFB2: Salaried Income Program
B3: Personal Loan | XFB3: Normal Income Program
B4: Application ID | F4: Proposal Date | L4: KEY METRICS | XFB4: Banking Surrogate Program
B5: Case Location | F5: Branch & Distance from branch | L5: Metric | M5: Value | N5: Unit | O5: Note / Norm | XFB5: GST/GTP Program
B6: Sourcing Done By | F6: Sourcing Channel | L6: Proposed Loan Amount | M6: =C20 -> 0 | N6: Lakhs | XFB6: Gross Receipts Program - Doctors
B7: Borrower Details | C7: S.No | D7: Applicant/Co-Applicant/Guarantor | E7: Name of Borrower | F7: Relationship | G7: Dependent (Y/N) | H7: Age at Loan Maturity | I7: Qualification | J7: Cibil Score | L7: Total Group Exposure | M7: =C21 -> 0 | N7: Lakhs | O7: Own exposure + existing group POS | XFB7: Repayment Track Record Program (RTR) Program | XFD7: SOIP
C8: 1 | D8: Applicant | L8: ROI (p.a.) | M8: =C22 -> 0 | N8: % | XFB8: Assessment Program | XFD8: SORP
C9: 2 | D9: Co-Applicant | L9: Tenure | M9: =G21 -> 0 | N9: Months | XFD9: Residential Property
C10: 3 | D10: Co-Applicant | L10: Approx. Proposed EMI | M10: =IFERROR('RTR '!J5,"-") -> - | N10: Rs | O10: Computed on proposed amount/tenor/ROI | XFD10: SOCP
C11: 4 | L11: Banking Turnover Ratio (BTO) | M11: =IFERROR(G23,"-") -> - | N11: x | O11: Annualised banking credits / proposed loan | XFD11: Commercial Property
C12: 5 | L12: ABB : EMI Ratio | M12: =IFERROR(Banking!H12,"-") -> - | N12: x | O12: Compare with applicable program norm | XFD12: Plot
C13: 6 | L13: Collateral LTV (Blended) | M13: =IFERROR('Collateral Details'!H7,"-") -> - | N13: % | O13: Policy norm ~60% for secured products (Product type sheet) | XFD13: SOIP+SORP
C14: 7 | L14: Total Policy Deviations Flagged | M14: =IFERROR('Deviation list'!I46,0) -> 2 | N14: count | O14: See Deviation Register below
C15: 8 | L15: Min CIBIL Score (Applicants) | M15: =IF(COUNT(J8:J17)=0,"-",_xlfn.MINIFS(J8:J17,J8:J17,">0")) -> - | N15: score
C16: 9 | L16: Max CIBIL Score (Applicants) | M16: =IF(COUNT(J8:J17)=0,"-",_xlfn.MAXIFS(J8:J17,J8:J17,">0")) -> - | N16: score
C17: 10 | L17: ELIGIBILITY CROSS-CHECK — ALL PROGRAMS | XFD17: SOIP+SOCP
B18: Product | C18: Personal Loan | L18: Program | M18: Eligible Amt | N18: Actual FOIR/Ratio | O18: Gap vs Proposed | P18: Status
B19: Program Type | C19: Salaried Income Program | F19: Scheme Code | G19: General Personal Loan | L19: Salaried Income Program | M19: =IFERROR('Eligibility-Salaried'!E20,"-") -> - | N19: =IFERROR('Eligibility-Salaried'!E22,"-") -> - | O19: =IF(ISNUMBER(M19),M19-$M$6,"-") -> - | P19: =IF(ISNUMBER(O19),IF(O19>=0,"Sufficient","Shortfall"),"Data pending") -> Data pending | XFD19: Multiple Properties
B20: Loan Amount / Exposure | C20: ='RTR '!J2/100000 -> 0 | E20: Lakhs | F20: Existing Group Exposure (POS) | G20: 0 | J20: =E20 -> Lakhs | L20: Normal / Business Income Program | M20: =IFERROR('Eligibility- Normal Income'!E20,"-") -> - | N20: =IFERROR('Eligibility- Normal Income'!E22,"-") -> - | O20: =IF(ISNUMBER(M20),M20-$M$6,"-") -> - | P20: =IF(ISNUMBER(O20),IF(O20>=0,"Sufficient","Shortfall"),"Data pending") -> Data pending | XFD20: NA
B21: Total Group Exposure | C21: =C20+G20 -> 0 | E21: =E20 -> Lakhs | F21: Tenure (Months) | G21: ='RTR '!J3 -> 0 | L21: Assessment Program (Trade/Business) | M21: =IFERROR('Eligibility -Assessment'!C8,"-") -> - | N21: =IFERROR('Eligibility -Assessment'!C10,"-") -> - | O21: =IF(ISNUMBER(M21),M21-$M$6,"-") -> - | P21: =IF(ISNUMBER(O21),IF(O21>=0,"Sufficient","Shortfall"),"Data pending") -> Data pending
B22: ROI | C22: ='RTR '!J4 -> 0 | F22: Processing Fees | L22: GST Program | M22: =IFERROR('Eligibility -Assessment'!C25,"-") -> - | N22: =IFERROR('Eligibility -Assessment'!C27,"-") -> - | O22: =IF(ISNUMBER(M22),M22-$M$6,"-") -> - | P22: =IF(ISNUMBER(O22),IF(O22>=0,"Sufficient","Shortfall"),"Data pending") -> Data pending
B23: FOIR | F23: BTO | G23: =Banking!M12 -> #DIV/0! | L23: GRP - Doctors Program | M23: =IFERROR('Eligibility -Assessment'!G23,"-") -> - | N23: =IFERROR('Eligibility -Assessment'!G25,"-") -> - | O23: =IF(ISNUMBER(M23),M23-$M$6,"-") -> - | P23: =IF(ISNUMBER(O23),IF(O23>=0,"Sufficient","Shortfall"),"Data pending") -> Data pending
B24: HL Loan amount | C24: 0 | E24: Lakhs | F24: ABB (Rs in Lakha) | G24: =Banking!E12 -> 0 | L24: RTR / BT Program | M24: =IFERROR('Eiligibility-RTR Sheet'!F21/100000,"-") -> - | N24: - | O24: =IF(ISNUMBER(M24),M24-$M$6,"-") -> - | P24: =IF(ISNUMBER(O24),IF(O24>=0,"Sufficient","Shortfall"),"Data pending") -> Data pending
B25: Insurance (%) | L25: Banking Surrogate Program | M25: =IFERROR('Eligibility - Banking Program'!M25,"-") -> - | N25: =IFERROR('Eligibility - Banking Program'!M24,"-") -> - | O25: =IF(ISNUMBER(M25),M25-$M$6,"-") -> - | P25: =IF(ISNUMBER(O25),IF(O25>=0,"Sufficient","Shortfall"),"Data pending") -> Data pending
B27: Existing Loan Details Sivels Finance | L27: Note: LTV norm (60%) is drawn from the Product type sheet for secured products; BTO/ABB:EMI thresholds should be validated against the current credit policy for the selected scheme code before sanction. Figures above recalc automatically as each linked sheet is filled in.
B29: Asset Creation | C29: S.No | D29: Type of Assets | E29: Year of Purchase | F29: Purchase Cost | G29: Market Value | H29: Property Owner | I29: Remarks
C30: 1
C31: 2
C32: 3
C33: 4
C34: 5
C35: ='Collateral Details'!A3 -> 2 | D35: =IF('Collateral Details'!B3="","",'Collateral Details'!B3) -> SOIP | E35: =IF('Collateral Details'!C3="","",'Collateral Details'!C3) | F35: =IF('Collateral Details'!D3="","",'Collateral Details'!D3) | G35: =IF('Collateral Details'!H3="","",'Collateral Details'!H3) -> 0.5
C36: ='Collateral Details'!A4 -> 3 | D36: =IF('Collateral Details'!B4="","",'Collateral Details'!B4) -> Plot | E36: =IF('Collateral Details'!C4="","",'Collateral Details'!C4) | F36: =IF('Collateral Details'!D4="","",'Collateral Details'!D4) | G36: =IF('Collateral Details'!H4="","",'Collateral Details'!H4) -> 0.4
C37: ='Collateral Details'!A5 -> 4 | D37: =IF('Collateral Details'!B5="","",'Collateral Details'!B5) -> Vacant Residential | E37: =IF('Collateral Details'!C5="","",'Collateral Details'!C5) | F37: =IF('Collateral Details'!D5="","",'Collateral Details'!D5) | G37: =IF('Collateral Details'!H5="","",'Collateral Details'!H5) -> 0.65
C38: ='Collateral Details'!A6 -> 5 | D38: =IF('Collateral Details'!B6="","",'Collateral Details'!B6) -> Rented Residential | E38: =IF('Collateral Details'!C6="","",'Collateral Details'!C6) | F38: =IF('Collateral Details'!D6="","",'Collateral Details'!D6) | G38: =IF('Collateral Details'!H6="","",'Collateral Details'!H6) -> 0.65
B39: Pre-payment Charges | C39: No foreclosure allowed up to 24 months of disbursement.
C40: Between 24 to 48 months, prepayment charges will be 4%+GST of outstanding loan amount and thereafter 2%+GST will be charged as prepayment charges on outstanding loan amount.
B41: Personal Discussion (PD)/ Site Visit (SV)
B42: Deal Structure
...

Sheet Collateral Details
A1: S. No. | B1: Type of Collateral | C1: Address of collateral | D1: Current Usage | E1: Valuation 1 | F1: Valuation 1 | G1: Lower Valuation | H1: LTV | I1: Loan Amount | J1: Legal vendor Name & Status | K1: Techncial Remarks (If any) | XFD1: Plot
A2: 1 | XFD2: SORP
A3: 2 | B3: SOIP | G3: =MIN(E3:F3) -> 0 | H3: 0.5 | I3: =G3*H3 -> 0 | XFD3: SOCP
A4: 3 | B4: Plot | G4: =MIN(E4:F4) -> 0 | H4: 0.4 | I4: =G4*H4 -> 0 | XFD4: SOIP
A5: 4 | B5: Vacant Residential | G5: =MIN(E5:F5) -> 0 | H5: 0.65 | I5: =G5*H5 -> 0 | XFD5: Rented Residential
A6: 5 | B6: Rented Residential | G6: =MIN(E6:F6) -> 0 | H6: 0.65 | I6: =G6*H6 -> 0 | XFD6: Rented Commercial
A7: Total | E7: =SUM(E2:E6) -> 0 | F7: =SUM(F2:F6) -> 0 | G7: =SUM(G2:G6) -> 0 | H7: =I7/G7 -> #DIV/0! | I7: =SUM(I2:I6) -> 0 | XFD7: Mixed usage
XFD8: Vacant Residential
XFD9: Vacant Commercial

Sheet GST
B1: Year | C1: Sales
B2: 46048
B3: 46016
B4: 45986
B5: 45955
B6: 45925
B7: 45894
B8: 45863
B9: 45833
B10: 45802
B11: 45772
B12: Total | C12: =SUM(C2:C11) -> 0
B13: Avg | C13: =C12/10 -> 0
B14: Annualized | C14: =C13*12 -> 0

Sheet RTR 
A1: Total Obligations - Live Loans | C1: Closure within 12 months & Proposed BT & Proposed to be closed from Sivels Finance | G1: Details of Proposed Loan | K1: Total Obligations including Sivels Finance
A2: POS (In Rs.) | B2: =SUMIF(F7:F46,1,I7:I46) -> 0 | C2: POS (In Rs.) | E2: =SUMIF(F7:F46,4,I7:I46) -> 0 | G2: Loan Amount (In Rs.) | K2: POS (In Rs.) | L2: =J2+B2 -> 0
A3: EMI (In Rs.) | B3: =SUMIF(F7:F46,1,H7:H46) -> 0 | C3: EMI (In Rs.) | E3: =SUMIF(F7:F46,4,H7:H46) -> 0 | G3: Tenor | K3: EMI (In Rs.) | L3: =J5+B3 -> #NUM!
A4: Personal Obligation not considered | C4: POS (In Rs.) | E4: =SUMIF(F7:F46,3,I7:I46) -> 0 | G4: ROI
C5: EMI (In Rs.) | E5: =SUMIF(F7:F46,3,H7:H46) -> 0 | G5: EMI | J5: =ROUND(PMT(J4/12,J3,-J2),0) -> #NUM!
A6: Name of Borrower | B6: Bank / Fi Name | C6: Account from where EMI served | D6: Product | E6: Status (Live / Closed) | G6: Loan Amount (In Rs.) | H6: EMI | I6: POS | J6: Reflected in CIBIL | K6: Start Date (dd/mm/yyyy) | L6: End Date | M6: Tenor (In months) | N6: Paid Tenor | O6: O/s Tenor | P6: No of bounce in Last 12 months | Q6: FOIR (Y/N) | R6: DPD's in CIBIL report | S6: Comment on RTR | T6: EMI due date eg. 5th of every month | U6: 46134 | V6: =+U6-30 -> 46104 | W6: =+V6-30 -> 46074 | X6: =+W6-30 -> 46044 | Y6: =+X6-30 -> 46014 | Z6: =+Y6-30 -> 45984 | AA6: =+Z6-30 -> 45954 | AB6: =+AA6-30 -> 45924 | AC6: =+AB6-30 -> 45894 | ... AF6: =+AE6-30 -> 45804
F7: =IF(E7="Live",1,IF(E7="Closed",2,IF(E7="Personal Obligation not considered",3,4))) -> 4
F8: =IF(E8="Live",1,IF(E8="Closed",2,IF(E8="Personal Obligation not considered",3,4))) -> 4
F9: =IF(E9="Live",1,IF(E9="Closed",2,IF(E9="Personal Obligation not considered",3,4))) -> 4 | O9: =+M9-N9 -> 0
F10: =IF(E10="Live",1,IF(E10="Closed",2,IF(E10="Personal Obligation not considered",3,4))) -> 4 | O10: =+M10-N10 -> 0
F11: =IF(E11="Live",1,IF(E11="Closed",2,IF(E11="Personal Obligation not considered",3,4))) -> 4 | O11: =+M11-N11 -> 0
F12: =IF(E12="Live",1,IF(E12="Closed",2,IF(E12="Personal Obligation not considered",3,4))) -> 4 | O12: =+M12-N12 -> 0
F13: =IF(E13="Live",1,IF(E13="Closed",2,IF(E13="Personal Obligation not considered",3,4))) -> 4 | O13: =+M13-N13 -> 0
F14: =IF(E14="Live",1,IF(E14="Closed",2,IF(E14="Personal Obligation not considered",3,4))) -> 4 | O14: =+M14-N14 -> 0
F15: =IF(E15="Live",1,IF(E15="Closed",2,IF(E15="Personal Obligation not considered",3,4))) -> 4 | O15: =+M15-N15 -> 0
F16: =IF(E16="Live",1,IF(E16="Closed",2,IF(E16="Personal Obligation not considered",3,4))) -> 4 | O16: =+M16-N16 -> 0
F17: =IF(E17="Live",1,IF(E17="Closed",2,IF(E17="Personal Obligation not considered",3,4))) -> 4 | O17: =+M17-N17 -> 0
F18: =IF(E18="Live",1,IF(E18="Closed",2,IF(E18="Personal Obligation not considered",3,4))) -> 4 | O18: =+M18-N18 -> 0
F19: =IF(E19="Live",1,IF(E19="Closed",2,IF(E19="Personal Obligation not considered",3,4))) -> 4 | O19: =+M19-N19 -> 0
F20: =IF(E20="Live",1,IF(E20="Closed",2,IF(E20="Personal Obligation not considered",3,4))) -> 4 | O20: =+M20-N20 -> 0
... F46: =IF(E46="Live",1,IF(E46="Closed",2,IF(E46="Personal Obligation not considered",3,4))) -> 4 | O46: =+M46-N46 -> 0

Sheet Banking
A2: Banking Analysis
A3: S.No. | B3: Bank Name | C3: Type of Account | D3: Annualised Business Credit summation | E3: ABB | F3: % I/w returns | G3: % O/w returns | H3: ABB / EMI | I3: Other remarks
A4: 1 | B4: =IFERROR(VLOOKUP(A4,$Q$14:$X$140,2,0)," ") | C4: =IFERROR(VLOOKUP(A4,$Q$14:$X$140,3,0)," ") | D4: =IFERROR(VLOOKUP(A4,$Q$14:$X$140,4,0)," ") | E4: =IFERROR(VLOOKUP(A4,$Q$14:$X$140,5,0)," ") | F4: =IFERROR(VLOOKUP(A4,$Q$14:$X$140,6,0)," ") | G4: =IFERROR(VLOOKUP(A4,$Q$14:$X$140,7,0)," ") | H4: =IFERROR(VLOOKUP(A4,$Q$14:$X$140,8,0)," ")
A5: 2 | B5: =IFERROR(VLOOKUP(A5,$Q$14:$X$140,2,0)," ") | C5: =IFERROR(VLOOKUP(A5,$Q$14:$X$140,3,0)," ") | D5: =IFERROR(VLOOKUP(A5,$Q$14:$X$140,4,0)," ") | E5: =IFERROR(VLOOKUP(A5,$Q$14:$X$140,5,0)," ") | F5: =IFERROR(VLOOKUP(A5,$Q$14:$X$140,6,0)," ") | G5: =IFERROR(VLOOKUP(A5,$Q$14:$X$140,7,0)," ") | H5: =IFERROR(VLOOKUP(A5,$Q$14:$X$140,8,0)," ")
A6: 3 | B6: =IFERROR(VLOOKUP(A6,$Q$14:$X$140,2,0)," ") | C6: =IFERROR(VLOOKUP(A6,$Q$14:$X$140,3,0)," ") | D6: =IFERROR(VLOOKUP(A6,$Q$14:$X$140,4,0)," ") | E6: =IFERROR(VLOOKUP(A6,$Q$14:$X$140,5,0)," ") | F6: =IFERROR(VLOOKUP(A6,$Q$14:$X$140,6,0)," ") | G6: =IFERROR(VLOOKUP(A6,$Q$14:$X$140,7,0)," ") | H6: =IFERROR(VLOOKUP(A6,$Q$14:$X$140,8,0)," ")
A7: 4 | B7: =IFERROR(VLOOKUP(A7,$Q$14:$X$140,2,0)," ") | C7: =IFERROR(VLOOKUP(A7,$Q$14:$X$140,3,0)," ") | D7: =IFERROR(VLOOKUP(A7,$Q$14:$X$140,4,0)," ") | E7: =IFERROR(VLOOKUP(A7,$Q$14:$X$140,5,0)," ") | F7: =IFERROR(VLOOKUP(A7,$Q$14:$X$140,6,0)," ") | G7: =IFERROR(VLOOKUP(A7,$Q$14:$X$140,7,0)," ") | H7: =IFERROR(VLOOKUP(A7,$Q$14:$X$140,8,0)," ")
A8: 5 | B8: =IFERROR(VLOOKUP(A8,$Q$14:$X$140,2,0)," ") | C8: =IFERROR(VLOOKUP(A8,$Q$14:$X$140,3,0)," ") | D8: =IFERROR(VLOOKUP(A8,$Q$14:$X$140,4,0)," ") | E8: =IFERROR(VLOOKUP(A8,$Q$14:$X$140,5,0)," ") | F8: =IFERROR(VLOOKUP(A8,$Q$14:$X$140,6,0)," ") | G8: =IFERROR(VLOOKUP(A8,$Q$14:$X$140,7,0)," ") | H8: =IFERROR(VLOOKUP(A8,$Q$14:$X$140,8,0)," ")
A9: 6 | B9: =IFERROR(VLOOKUP(A9,$Q$14:$X$140,2,0)," ") | C9: =IFERROR(VLOOKUP(A9,$Q$14:$X$140,3,0)," ") | D9: =IFERROR(VLOOKUP(A9,$Q$14:$X$140,4,0)," ") | E9: =IFERROR(VLOOKUP(A9,$Q$14:$X$140,5,0)," ") | F9: =IFERROR(VLOOKUP(A9,$Q$14:$X$140,6,0)," ") | G9: =IFERROR(VLOOKUP(A9,$Q$14:$X$140,7,0)," ") | H9: =IFERROR(VLOOKUP(A9,$Q$14:$X$140,8,0)," ")
A10: 7 | B10: =IFERROR(VLOOKUP(A10,$Q$14:$X$140,2,0)," ") | C10: =IFERROR(VLOOKUP(A10,$Q$14:$X$140,3,0)," ") | D10: =IFERROR(VLOOKUP(A10,$Q$14:$X$140,4,0)," ") | E10: =IFERROR(VLOOKUP(A10,$Q$14:$X$140,5,0)," ") | F10: =IFERROR(VLOOKUP(A10,$Q$14:$X$140,6,0)," ") | G10: =IFERROR(VLOOKUP(A10,$Q$14:$X$140,7,0)," ") | H10: =IFERROR(VLOOKUP(A10,$Q$14:$X$140,8,0)," ")
A11: 8 | B11: =IFERROR(VLOOKUP(A11,$Q$14:$X$140,2,0)," ") | C11: =IFERROR(VLOOKUP(A11,$Q$14:$X$140,3,0)," ") | D11: =IFERROR(VLOOKUP(A11,$Q$14:$X$140,4,0)," ") | E11: =IFERROR(VLOOKUP(A11,$Q$14:$X$140,5,0)," ") | F11: =IFERROR(VLOOKUP(A11,$Q$14:$X$140,6,0)," ") | G11: =IFERROR(VLOOKUP(A11,$Q$14:$X$140,7,0)," ") | H11: =IFERROR(VLOOKUP(A11,$Q$14:$X$140,8,0)," ")
A12: Total | D12: =SUM(D4:D11) -> 0 | E12: =SUM(E4:E11) -> 0 | F12: =(G29+G47+G65+G83+G101+G119+G137+G155)/(E119+E101+E83+E65+E47+E29+E155+E137) -> #DIV/0! | G12: =(H29+H47+H65+H83+H101+H119+H137+H155)/(F119+F101+F83+F65+F47+F29+F155+F137) -> #DIV/0! | H12: =E12/'RTR '!J5 -> #NUM! | I12: BTO | M12: =(D12)/'Consolidated Fin'!D5 -> #DIV/0!
A14: A/c Holder Name | D14: Bank Name | H14: Account Type- | K14: Account No | O14: =IF(F14=0,0,1) -> 0 | P14: =O14 -> 0 | Q14: =IF(O14>0,P14,0) -> 0 | R14: =F14 -> 0 | S14: =I14 -> 0 | T14: =B30 -> 0 | U14: =L29 -> 0 | V14: =G30 -> 0 | W14: =H30 -> 0 | X14: =M29 -> #NUM!
A15: Banking -1 | B15: Amount of Transactions | E15: No of Transactions | G15: Bounce Data | I15: Bank Balance | L15: ABB | M15: ABB / EMI
A16: MONTHS | B16: Monthly Credits | C16: Monthly Credits non Business Related | D16: Monthly Debits | E16: No. of Debits | F16: No. of Credits | G16: I/W Bounces | H16: O/W Bounces | I16: DAY 5th Balance | J16: DAY 15th Balance | K16: DAY 25th Balance
A17: 46134 | L17: =IFERROR((AVERAGE(I17:K17)),0) -> 0 | M17: =(L17)/'RTR '!$J$5 -> #NUM!
A18: =A17-30 -> 46104 | L18: =IFERROR((AVERAGE(I18:K18)),0) -> 0 | M18: =(L18)/'RTR '!$J$5 -> #NUM!
A19: =A18-30 -> 46074 | L19: =IFERROR((AVERAGE(I19:K19)),0) -> 0 | M19: =(L19)/'RTR '!$J$5 -> #NUM!
A20: =A19-30 -> 46044 | L20: =IFERROR((AVERAGE(I20:K20)),0) -> 0 | M20: =(L20)/'RTR '!$J$5 -> #NUM!
A21: =A20-30 -> 46014 | L21: =IFERROR((AVERAGE(I21:K21)),0) -> 0 | M21: =(L21)/'RTR '!$J$5 -> #NUM!
A22: =A21-30 -> 45984 | L22: =IFERROR((AVERAGE(I22:K22)),0) -> 0 | M22: =(L22)/'RTR '!$J$5 -> #NUM!
A23: =A22-30 -> 45954 | L23: =IFERROR((AVERAGE(I23:K23)),0) -> 0 | M23: =(L23)/'RTR '!$J$5 -> #NUM!
A24: =A23-30 -> 45924 | L24: =IFERROR((AVERAGE(I24:K24)),0) -> 0 | M24: =(L24)/'RTR '!$J$5 -> #NUM!
A25: =A24-30 -> 45894 | L25: =IFERROR((AVERAGE(I25:K25)),0) -> 0 | M25: =(L25)/'RTR '!$J$5 -> #NUM!
A26: =A25-30 -> 45864 | L26: =IFERROR((AVERAGE(I26:K26)),0) -> 0 | M26: =(L26)/'RTR '!$J$5 -> #NUM!
A27: =A26-30 -> 45834 | L27: =IFERROR((AVERAGE(I27:K27)),0) -> 0 | M27: =(L27)/'RTR '!$J$5 -> #NUM!
A28: =A27-30 -> 45804 | L28: =IFERROR((AVERAGE(I28:K28)),0) -> 0 | M28: =(L28)/'RTR '!$J$5 -> #NUM!
A29: Avg Receipts | B29: =IFERROR(AVERAGE(B17:B28),0) -> 0 | C29: =IFERROR(AVERAGE(C17:C28),0) -> 0 | D29: =IFERROR(AVERAGE(D17:D28),0) -> 0 | E29: =SUM(E17:E28) -> 0 | F29: =SUM(F17:F28) -> 0 | G29: =SUM(G17:G28) -> 0 | H29: =SUM(H17:H28) -> 0 | L29: =IFERROR(AVERAGE(I17:K28),0) -> 0 | M29: =(L29)/'RTR '!J5 -> #NUM!
A30: ANNUALISED | B30: =IF(B29=0,0,((SUM(B17:B28)/COUNT(B17:B28))*12)) -> 0 | C30: =IF(C29=0,0,((SUM(C17:C28)/COUNT(C17:C28))*12)) -> 0 | D30: =IF(D29=0,0,((SUM(D17:D28)/COUNT(D17:D28))*12)) -> 0 | E30: Bounce % | G30: =IF(IFERROR(G29/E29,0),G29/E29,0) -> 0 | H30: =IF(IFERROR(H29/F29,0),H29/F29,0) -> 0
A32: A/c Holder Name | D32: Bank Name | H32: Account Type- | I32: Saving | K32: Account No | O32: =IF(F32=0,0,1) -> 0 | P32: =O32+P14 -> 0 | Q32: =IF(O32>0,P32,0) -> 0 | R32: =F32 -> 0 | S32: =I32 -> Saving | T32: =B48 -> 0 | U32: =L47 -> 0 | V32: =G48 -> 0 | W32: =H48 -> 0 | X32: =M47 -> #NUM!
A33: Banking -2 | B33: Amount of Transactions | E33: No of Transactions | G33: Bounce Data | I33: Bank Balance | L33: ABB | M33: ABB / EMI
A34: MONTHS | B34: Monthly Credits | C34: Monthly Credits non Business Related | D34: Monthly Debits | E34: No. of Debits | F34: No. of Credits | G34: I/W Bounces | H34: O/W Bounces | I34: DAY 5th Balance | J34: DAY 15th Balance | K34: DAY 25th Balance
A35: 46103 | L35: =IFERROR((AVERAGE(I35:K35)),0) -> 0 | M35: =(L35)/'RTR '!$J$5 -> #NUM!
A36: =A35-30 -> 46073 | L36: =IFERROR((AVERAGE(I36:K36)),0) -> 0 | M36: =(L36)/'RTR '!$J$5 -> #NUM!
A37: =A36-30 -> 46043 | L37: =IFERROR((AVERAGE(I37:K37)),0) -> 0 | M37: =(L37)/'RTR '!$J$5 -> #NUM!
A38: =A37-30 -> 46013 | L38: =IFERROR((AVERAGE(I38:K38)),0) -> 0 | M38: =(L38)/'RTR '!$J$5 -> #NUM!
A39: =A38-30 -> 45983 | L39: =IFERROR((AVERAGE(I39:K39)),0) -> 0 | M39: =(L39)/'RTR '!$J$5 -> #NUM!
A40: =A39-30 -> 45953 | L40: =IFERROR((AVERAGE(I40:K40)),0) -> 0 | M40: =(L40)/'RTR '!$J$5 -> #NUM!
A41: =A40-30 -> 45923 | L41: =IFERROR((AVERAGE(I41:K41)),0) -> 0 | M41: =(L41)/'RTR '!$J$5 -> #NUM!
A42: =A41-30 -> 45893 | L42: =IFERROR((AVERAGE(I42:K42)),0) -> 0 | M42: =(L42)/'RTR '!$J$5 -> #NUM!
A43: =A42-30 -> 45863 | L43: =IFERROR((AVERAGE(I43:K43)),0) -> 0 | M43: =(L43)/'RTR '!$J$5 -> #NUM!
...

Sheet Eligibility-Salaried
A1: Sr. No. | B1: Component | C1: Amount as per Salary slip | D1: Consideration | E1: Eligible Amount
B2: Salaried Income
A3: A.1 | B3: Net salary as per salary slip | D3: 1 | E3: =D3*C3 -> 0
A4: A.2 | B4: Fixed bonus (monthly/quarterly) if forming a part of salary slip | C4: 0 | D4: 1 | E4: =D4*C4 -> 0
A5: A.3 | B5: Performance linked bonus/incentives (monthly) | D5: 1 | E5: =D5*C5 -> 0
A6: A.4 | B6: Monthly perquisites in the form of meal vouchers | D6: 0.5 | E6: =D6*C6 -> 0
A7: A.5 | B7: Reimbursements as a part of CTC | D7: 0.5 | E7: =D7*C7 -> 0
A8: A | B8: Total Salaried Income (A.1+A.2+A.3+A.4+ A.5) | E8: =SUM(E3:E7) -> 0
B9: Other Income
A10: B.1 | B10: House Property (Per month) | C10: 0 | D10: 1 | E10: =D10*C10 -> 0
A11: B.2 | B11: Agriculture Income (Per month) | C11: 0 | D11: 0.5 | E11: =D11*C11 -> 0
A12: B.3 | B12: Income from Other Sources (Per month) | C12: 0 | D12: 0.5 | E12: =D12*C12 -> 0
A13: B.4 | B13: Total Other Income (B.1+ B.2+ B.3) | E13: =SUM(E10:E12) -> 0
A14: B | B14: Total Other Income to be considered | C14: Restricted to maximum 100% of Salaried Income | D14: Yes | E14: =IF(D14="Yes",IF(E13>E8,E8,E13),E13) -> 0
A15: C | B15: Total Monthly Income (A+B) | E15: =E14+E8 -> 0
A16: D | B16: Total Eligible Monthly Income (C*FOIR) | D16: 0.6 | E16: =E15*D16 -> 0
A17: E | B17: Existing Monthly Obligations | E17: ='RTR '!B3 -> 0
A18: F | B18: Net Serviceable Income (D-E) | E18: =E16-E17 -> 0
A19: G | B19: EMI Factor @IRR/Tenor | E19: =PMT('RTR '!J4/12,'RTR '!J3,-100000) -> #NUM!
A20: H | B20: Loan Eligibility (F/G) | E20: =E18/E19 -> #NUM!
A21: I | B21: Proposed Loan Amount (in lacs) | E21: ='RTR '!J2/100000 -> 0
A22: J | B22: Actual FOIR | E22: ='RTR '!L3/'Eligibility-Salaried'!E15 -> #NUM!

Sheet Eligibility- Normal Income
A1: Sr. No. | B1: Component | C1: ='Consolidated Fin'!C4 -> 45747 | D1: ='Consolidated Fin'!D4 -> 46112 | E1: Considered for Eligibility Amount
B2: Primary Income
A3: A.1 | B3: PAT | C3: ='Consolidated Fin'!D27 -> 0 | D3: ='Consolidated Fin'!C27 -> 0
A4: A.2 | B4: Depreciation | C4: ='Consolidated Fin'!C21 -> 0 | D4: ='Consolidated Fin'!D21 -> 0
A5: A.3 | B5: Salary to partners | C5: ='Consolidated Fin'!C22 -> 0 | D5: ='Consolidated Fin'!D22 -> 0
A6: A.4 | B6: Interest Paid to related parties/partners/directors | C6: ='Consolidated Fin'!C20 -> 0 | D6: ='Consolidated Fin'!D20 -> 0
A7: A | B7: Primary Income P.a. (A.1 to A.5) | C7: =SUM(C3:C6) -> 0 | D7: =SUM(D3:D6) -> 0 | E7: =SUM(E3:E6) -> 0
A8: B | B8: Salary Income (if anyone is salaried) P.a. | E8: ='Eligibility-Salaried'!E8*12 -> 0
B9: Other Income
A10: C.1 | B10: House Property (Per Annum) | D10: 1 | E10: =D10*C10 -> 0
A11: C.2 | B11: Agriculture Income (Per Annum) | D11: 0.5 | E11: =D11*C11 -> 0
A12: C.3 | B12: Income from Other Sources (Per Annum) | D12: 0.5 | E12: =D12*C12 -> 0
A13: C.4 | B13: Total Other Income (B.1+ B.2+ B.3) | E13: =SUM(E10:E12) -> 0
A14: C | B14: Total Other Income to be considered | C14: Restricted to maximum 100% of Business Income | D14: No | E14: =IF(D14="Yes",IF(E13>(E8+E7),E8,E13),E13) -> 0
A15: D | B15: Total Income (A+B+C) (Per Annum) | E15: =E14+E8+E7 -> 0
A16: E | B16: Total Eligible Monthly Income (A+B*FOIR @ 70%+C*60%)/12 | E16: =((E14+E7)*0.7+E8*0.6)/12 -> 0
A17: F | B17: Existing Monthly Obligations | E17: ='RTR '!B3 -> 0
A18: G | B18: Net Serviceable Income (E-F) | E18: =E16-E17 -> 0
A19: H | B19: EMI Factor @IRR/Tenor | E19: =PMT('RTR '!J4/12,'RTR '!J3,-100000) -> #NUM!
A20: I | B20: Loan Eligibility (G/H) | E20: =E18/E19 -> #NUM!
A21: J | B21: Proposed Loan Amount (in lacs) | E21: ='RTR '!J2/100000 -> 0
A22: K | B22: Actual FOIR | E22: ='RTR '!L3/(E15/12) -> #NUM!

Sheet Eiligibility-RTR Sheet
B1: RTR Norms
B2: RTR | C2: 12-24 MOB | D2: 25-36 MOB | E2: >36 MOB
B3: OD as per CIR | C3: Nil | D3: 1 (Never in 30+ during MOB) | E3: 2 (Never in 30+ during MOB)
B4: Bounce (as per SOA) | C4: <=2 | D4: <=3 | E4: <=4
B5: Multiplier on EMI | C5: 1.5x | D5: 1.75x | E5: 2.00x
B6: Max Topup | C6: upto 50% of BT amount | D6: upto 100% of BT amount | E6: upto 200% of BT amount
B8: BT Loan Details and Eligibility Calculation
C9: BT Loan 1 | D9: BT Loan 2 | E9: BT Loan 3 | F9: Total
B10: Sanction Amount | F10: =SUM(C10:E10) -> 0
B11: Current POS | F11: =SUM(C11:E11) -> 0
B12: EMI Start Date
B13: EMI Amount | F13: =SUM(C13:E13) -> 0
B14: MOB
B15: OD as per CIR
B16: Bounce (as per SOA)
B17: Multiplier on EMI | C17: =IF(C14>36,2,IF(C14>24,1.75,IF(C14>11,1.5,0))) -> 0 | D17: =IF(D14>36,2,IF(D14>24,1.75,IF(D14>11,1.5,0))) -> 0 | E17: =IF(E14>36,2,IF(E14>24,1.75,IF(E14>11,1.5,0))) -> 0
B18: Max Topup | C18: =IF(C14>36,C11*2,IF(C14>24,C11,IF(C14>11,C11*0.5,0))) -> 0 | D18: =IF(D14>36,D11*2,IF(D14>24,D11,IF(D14>11,D11*0.5,0))) -> 0 | E18: =IF(E14>36,E11*2,IF(E14>24,E11,IF(E14>11,E11*0.5,0))) -> 0 | F18: =SUM(C18:E18) -> 0
B19: Assessed Income | C19: =C17*C13 -> 0 | D19: =D17*D13 -> 0 | E19: =E17*E13 -> 0 | F19: =SUM(C19:E19) -> 0
B20: EMI Factor @IRR/Tenor | F20: =PMT('RTR '!J4/12,'RTR '!J3,-100000) -> #NUM!
B21: Loan Eligibility (G/H) | F21: =MIN(F19/F20*100000,(F18+F11)) -> #NUM!

Sheet Eligibility -Assessment
A1: Eligibility Calculation as per Assessment Program | E1: Assessed EBIDTA Margin
E2: Sales last Year | G2: 100
A3: A | B3: Net Monthly Income as per memorandum of monthly income and expenditure statement | E3: Less: Expenses
A4: B | B4: Total Eligible Monthly Income ((B-C)* FOIR%)/12 | C4: =C3*0.55 -> 0 | E4: Cost of Goods Sold
A5: C | B5: Existing Monthly Loan Obligations | C5: ='RTR '!B3 -> 0 | E5: Salary
A6: D | B6: Net Serviceable Income (B-C) | C6: =C4-C5 -> 0 | E6: Rent
A7: E | B7: EMI Factor @IRR/Tenor | C7: =PMT('RTR '!J4/12,'RTR '!J3,-100000) -> #NUM! | E7: Electricity
A8: F | B8: Loan Eligibility (E/F) | C8: =C6/C7 -> #NUM! | E8: Other Office Administrative Expense
A9: G | B9: Proposed Loan Amount (in lacs) | C9: ='RTR '!J2/100000 -> 0 | E9: Total Expense | G9: =SUM(F4:F8) -> 0
A10: H | B10: Actual FOIR | C10: ='RTR '!L3/C3 -> #NUM! | E10: Assessed EBIDTA | G10: =G2-G9 -> 100
E11: Actual EBITDA Margin | F11: (Surplus/Total) | G11: =G10/G2 -> 1
A12: Eligibility Calculation as per GST Program
E13: Eligibility Calculation as per GRP - Doctors Program
A14: A | B14: Annual Turnover as per GST returns/Financials
A15: B | B15: Margin to be considered to be lower of: | C15: =MIN(C16:C18) -> 0.06 | E15: A | F15: Average Gross Receipts of last 2 years
B16: Assessed EBIDTA Margin % as assessed during PD | E16: B1 | F16: Multiplier as per policy (A* 2.5/2)
B17: Or | E17: B2 | F17: Total Income | G17: =G15*G16 -> 0
B18: Deemed Margin of 10% (service), 6% (Trading) and 8% (Manufacturing) | C18: 0.06 | E18: C | F18: Income Tax Paid | G18: 0
A19: C | B19: Annual Income (A*B) | C19: =(C14*C15) -> 0 | E19: D | F19: Total Eligible Monthly Income ((B-C)* FOIR%) | G19: =((G17-G18)*0.65)/12 -> 0
A20: D | B20: Income Tax paid (latest year) | C20: 0 | E20: E | F20: Existing Monthly Loan Obligations | G20: ='RTR '!B3 -> 0
A21: E | B21: Total Eligible Monthly Income ((C-D)* FOIR%)/12 | C21: =((C19-C20)*0.65)/12 -> 0 | E21: F | F21: Net Serviceable Income (C-D) | G21: =G19-G20 -> 0
A22: F | B22: Existing Monthly Loan Obligations | C22: ='RTR '!B3 -> 0 | E22: G | F22: EMI Factor @IRR/Tenor | G22: =PMT('RTR '!J4/12,'RTR '!J3,-100000) -> #NUM!
A23: G | B23: Net Serviceable Income (E-F) | C23: =C21-C22 -> 0 | E23: H | F23: Loan Eligibility (E/F) | G23: =G21/G22 -> #NUM!
A24: H | B24: EMI Factor @IRR/Tenor | C24: =PMT('RTR '!J4/12,'RTR '!J3,-100000) -> #NUM! | E24: I | F24: Proposed Loan Amount (in lacs) | G24: ='RTR '!J2/100000 -> 0
A25: I | B25: Loan Eligibility (G/H) | C25: =C23/C24 -> #NUM! | E25: J | F25: Actual FOIR | G25: ='RTR '!L3/((G17-G18)/12) -> #NUM!
A26: J | B26: Proposed Loan Amount (in lacs) | C26: ='RTR '!J2/100000 -> 0
A27: K | B27: Actual FOIR | C27: ='RTR '!L3/((C19-C20)/12) -> #NUM!

Sheet Eligibility - Banking Program
A1: Eligibility Sheet - Banking Program
A2: Consolidation of max 3 Banking
A3: Banking -1 | B3: Amount of Transactions | E3: No of Transactions | G3: Bounce Data | I3: Bank Balance | L3: ABB | M3: ABB / EMI
A4: MONTHS | B4: Monthly Credits | C4: Monthly Credits non Business Related | D4: Monthly Debits | E4: No. of Debits | F4: No. of Credits | G4: I/W Bounces | H4: O/W Bounces | I4: DAY 5th Balance | J4: DAY 15th Balance | K4: DAY 25th Balance
A5: =Banking!A17 -> 46134 | B5: =Banking!B17+Banking!B35+Banking!B53 -> 0 | C5: =Banking!C17+Banking!C35+Banking!C53 -> 0 | D5: =Banking!D17+Banking!D35+Banking!D53 -> 0 | E5: =Banking!E17+Banking!E35+Banking!E53 -> 0 | F5: =Banking!F17+Banking!F35+Banking!F53 -> 0 | G5: =Banking!G17+Banking!G35+Banking!G53 -> 0 | H5: =Banking!H17+Banking!H35+Banking!H53 -> 0 | I5: =Banking!I17+Banking!I35+Banking!I53 -> 0 | ... K5: =Banking!K17+Banking!K35+Banking!K53 -> 0 | L5: =IFERROR((AVERAGE(I5:K5)),0) -> 0 | M5: =(L5)/'RTR '!$J$5 -> #NUM!
A6: =A5-30 -> 46104 | B6: =Banking!B18+Banking!B36+Banking!B54 -> 0 | C6: =Banking!C18+Banking!C36+Banking!C54 -> 0 | D6: =Banking!D18+Banking!D36+Banking!D54 -> 0 | E6: =Banking!E18+Banking!E36+Banking!E54 -> 0 | F6: =Banking!F18+Banking!F36+Banking!F54 -> 0 | G6: =Banking!G18+Banking!G36+Banking!G54 -> 0 | H6: =Banking!H18+Banking!H36+Banking!H54 -> 0 | I6: =Banking!I18+Banking!I36+Banking!I54 -> 0 | ... K6: =Banking!K18+Banking!K36+Banking!K54 -> 0 | L6: =IFERROR((AVERAGE(I6:K6)),0) -> 0 | M6: =(L6)/'RTR '!$J$5 -> #NUM!
A7: =A6-30 -> 46074 | B7: =Banking!B19+Banking!B37+Banking!B55 -> 0 | C7: =Banking!C19+Banking!C37+Banking!C55 -> 0 | D7: =Banking!D19+Banking!D37+Banking!D55 -> 0 | E7: =Banking!E19+Banking!E37+Banking!E55 -> 0 | F7: =Banking!F19+Banking!F37+Banking!F55 -> 0 | G7: =Banking!G19+Banking!G37+Banking!G55 -> 0 | H7: =Banking!H19+Banking!H37+Banking!H55 -> 0 | I7: =Banking!I19+Banking!I37+Banking!I55 -> 0 | ... K7: =Banking!K19+Banking!K37+Banking!K55 -> 0 | L7: =IFERROR((AVERAGE(I7:K7)),0) -> 0 | M7: =(L7)/'RTR '!$J$5 -> #NUM!
A8: =A7-30 -> 46044 | B8: =Banking!B20+Banking!B38+Banking!B56 -> 0 | C8: =Banking!C20+Banking!C38+Banking!C62 -> 0 | D8: =Banking!D20+Banking!D38+Banking!D56 -> 0 | E8: =Banking!E20+Banking!E38+Banking!E56 -> 0 | F8: =Banking!F20+Banking!F38+Banking!F56 -> 0 | G8: =Banking!G20+Banking!G38+Banking!G56 -> 0 | H8: =Banking!H20+Banking!H38+Banking!H56 -> 0 | I8: =Banking!I20+Banking!I38+Banking!I56 -> 0 | J8: =Banking!J20+Banking!J38+Banking!J56 -> 0 | K8: =Banking!K20+Banking!K38+Banking!K56 -> 0 | L8: =IFERROR((AVERAGE(I8:K8)),0) -> 0 | M8: =(L8)/'RTR '!$J$5 -> #NUM!
A9: =A8-30 -> 46014 | B9: =Banking!B21+Banking!B39+Banking!B57 -> 0 | C9: =Banking!C21+Banking!C39+Banking!C57 -> 0 | D9: =Banking!D21+Banking!D39+Banking!D57 -> 0 | E9: =Banking!E21+Banking!E39+Banking!E57 -> 0 | F9: =Banking!F21+Banking!F39+Banking!F57 -> 0 | G9: =Banking!G21+Banking!G39+Banking!G57 -> 0 | H9: =Banking!H21+Banking!H39+Banking!H57 -> 0 | I9: =Banking!I21+Banking!I39+Banking!I57 -> 0 | ... K9: =Banking!K21+Banking!K39+Banking!K57 -> 0 | L9: =IFERROR((AVERAGE(I9:K9)),0) -> 0 | M9: =(L9)/'RTR '!$J$5 -> #NUM!
A10: =A9-30 -> 45984 | B10: =Banking!B22+Banking!B40+Banking!B58 -> 0 | C10: =Banking!C22+Banking!C40+Banking!C58 -> 0 | D10: =Banking!D22+Banking!D40+Banking!D58 -> 0 | E10: =Banking!E22+Banking!E40+Banking!E58 -> 0 | F10: =Banking!F22+Banking!F40+Banking!F58 -> 0 | G10: =Banking!G22+Banking!G40+Banking!G58 -> 0 | H10: =Banking!H22+Banking!H40+Banking!H58 -> 0 | I10: =Banking!I22+Banking!I40+Banking!I58 -> 0 | ... K10: =Banking!K22+Banking!K40+Banking!K58 -> 0 | L10: =IFERROR((AVERAGE(I10:K10)),0) -> 0 | M10: =(L10)/'RTR '!$J$5 -> #NUM!
A11: =A10-30 -> 45954 | B11: =Banking!B23+Banking!B41+Banking!B59 -> 0 | C11: =Banking!C23+Banking!C41+Banking!C59 -> 0 | D11: =Banking!D23+Banking!D41+Banking!D59 -> 0 | E11: =Banking!E23+Banking!E41+Banking!E59 -> 0 | F11: =Banking!F23+Banking!F41+Banking!F59 -> 0 | G11: =Banking!G23+Banking!G41+Banking!G59 -> 0 | H11: =Banking!H23+Banking!H41+Banking!H59 -> 0 | I11: =Banking!I23+Banking!I41+Banking!I59 -> 0 | ... K11: =Banking!K23+Banking!K41+Banking!K59 -> 0 | L11: =IFERROR((AVERAGE(I11:K11)),0) -> 0 | M11: =(L11)/'RTR '!$J$5 -> #NUM!
A12: =A11-30 -> 45924 | B12: =Banking!B24+Banking!B42+Banking!B60 -> 0 | C12: =Banking!C24+Banking!C42+Banking!C60 -> 0 | D12: =Banking!D24+Banking!D42+Banking!D60 -> 0 | E12: =Banking!E24+Banking!E42+Banking!E60 -> 0 | F12: =Banking!F24+Banking!F42+Banking!F60 -> 0 | G12: =Banking!G24+Banking!G42+Banking!G60 -> 0 | H12: =Banking!H24+Banking!H42+Banking!H60 -> 0 | I12: =Banking!I24+Banking!I42+Banking!I60 -> 0 | ... K12: =Banking!K24+Banking!K42+Banking!K60 -> 0 | L12: =IFERROR((AVERAGE(I12:K12)),0) -> 0 | M12: =(L12)/'RTR '!$J$5 -> #NUM!
A13: =A12-30 -> 45894 | B13: =Banking!B25+Banking!B43+Banking!B61 -> 0 | C13: =Banking!C25+Banking!C43+Banking!C61 -> 0 | D13: =Banking!D25+Banking!D43+Banking!D61 -> 0 | E13: =Banking!E25+Banking!E43+Banking!E61 -> 0 | F13: =Banking!F25+Banking!F43+Banking!F61 -> 0 | G13: =Banking!G25+Banking!G43+Banking!G61 -> 0 | H13: =Banking!H25+Banking!H43+Banking!H61 -> 0 | I13: =Banking!I25+Banking!I43+Banking!I61 -> 0 | ... K13: =Banking!K25+Banking!K43+Banking!K61 -> 0 | L13: =IFERROR((AVERAGE(I13:K13)),0) -> 0 | M13: =(L13)/'RTR '!$J$5 -> #NUM!
A14: =A13-30 -> 45864 | B14: =Banking!B26+Banking!B44+Banking!B62 -> 0 | C14: =Banking!C26+Banking!C44+Banking!C62 -> 0 | D14: =Banking!D26+Banking!D44+Banking!D62 -> 0 | E14: =Banking!E26+Banking!E44+Banking!E62 -> 0 | F14: =Banking!F26+Banking!F44+Banking!F62 -> 0 | G14: =Banking!G26+Banking!G44+Banking!G62 -> 0 | H14: =Banking!H26+Banking!H44+Banking!H62 -> 0 | I14: =Banking!I26+Banking!I44+Banking!I62 -> 0 | ... K14: =Banking!K26+Banking!K44+Banking!K62 -> 0 | L14: =IFERROR((AVERAGE(I14:K14)),0) -> 0 | M14: =(L14)/'RTR '!$J$5 -> #NUM!
A15: =A14-30 -> 45834 | B15: =Banking!B27+Banking!B45+Banking!B63 -> 0 | C15: =Banking!C27+Banking!C45+Banking!C63 -> 0 | D15: =Banking!D27+Banking!D45+Banking!D63 -> 0 | E15: =Banking!E27+Banking!E45+Banking!E63 -> 0 | F15: =Banking!F27+Banking!F45+Banking!F63 -> 0 | G15: =Banking!G27+Banking!G45+Banking!G63 -> 0 | H15: =Banking!H27+Banking!H45+Banking!H63 -> 0 | I15: =Banking!I27+Banking!I45+Banking!I63 -> 0 | ... K15: =Banking!K27+Banking!K45+Banking!K63 -> 0 | L15: =IFERROR((AVERAGE(I15:K15)),0) -> 0 | M15: =(L15)/'RTR '!$J$5 -> #NUM!
A16: =A15-30 -> 45804 | B16: =Banking!B28+Banking!B46+Banking!B64 -> 0 | C16: =Banking!C28+Banking!C46+Banking!C64 -> 0 | D16: =Banking!D28+Banking!D46+Banking!D64 -> 0 | E16: =Banking!E28+Banking!E46+Banking!E64 -> 0 | F16: =Banking!F28+Banking!F46+Banking!F64 -> 0 | G16: =Banking!G28+Banking!G46+Banking!G64 -> 0 | H16: =Banking!H28+Banking!H46+Banking!H64 -> 0 | I16: =Banking!I28+Banking!I46+Banking!I64 -> 0 | ... K16: =Banking!K28+Banking!K46+Banking!K64 -> 0 | L16: =IFERROR((AVERAGE(I16:K16)),0) -> 0 | M16: =(L16)/'RTR '!$J$5 -> #NUM!
A17: Avg Receipts | B17: =IFERROR(AVERAGE(B5:B16),0) -> 0 | C17: =IFERROR(AVERAGE(C5:C16),0) -> 0 | D17: =IFERROR(AVERAGE(D5:D16),0) -> 0 | E17: =SUM(E5:E16) -> 0 | F17: =SUM(F5:F16) -> 0 | G17: =SUM(G5:G16) -> 0 | H17: =SUM(H5:H16) -> 0 | L17: =IFERROR(AVERAGE(I5:K16),0) -> 0 | M17: =(L17)/'RTR '!J5 -> #NUM!
A18: ANNUALISED | B18: =IF(B17=0,0,((SUM(B5:B16)/COUNT(B5:B16))*12)) -> 0 | C18: =IF(C17=0,0,((SUM(C5:C16)/COUNT(C5:C16))*12)) -> 0 | D18: =IF(D17=0,0,((SUM(D5:D16)/COUNT(D5:D16))*12)) -> 0 | E18: Bounce % | G18: =IF(IFERROR(G17/E17,0),G17/E17,0) -> 0 | H18: =IF(IFERROR(H17/F17,0),H17/F17,0) -> 0
A19: Eligibility Sheet | I19: EMI Started in last 3 months | M19: 0
I20: Proposed Loan Amount (in Lacs) | M20: ='RTR '!J2/100000 -> 0
I21: Interest Rate % | M21: ='RTR '!J4 -> 0
I22: Proposed Loan Tenure (months) | M22: ='RTR '!J3 -> 0
I23: Proposed EMI | M23: =(PMT(M21/12,M22,-M20*10^5)) -> #NUM!
I24: ABB : EMI | M24: =(L17-M19)/(M23) -> #NUM!
I25: Loan Eligibility (Rs in Lacs) @ 2 x ABB | M25: =(L17-M19)/(2*(PMT(M21/12,M22,-100000))) -> #NUM!
A27: r

Sheet Eligibility Computation
B3: Particulars | C3: in rs
B4: Monthly takehome | C4: ='Cashflow assessment'!B21 -> 0
B5: EMI obligations | C5: ='RTR '!B3 -> 0
B6: Proposed EMI for Rs.40 Lacs/ 120 months | C6: ='RTR '!J5 -> #NUM!
B7: Total EMI commitment | C7: =C5+C6 -> #NUM!
B8: FOIR | C8: =C7/C4 -> #NUM!

Sheet Cashflow assessment
A2: Computation of Profit/Loss for M/s.....................(Monthly Computations- Assessed Profile) | H2: Sr. No. | I2: Statement of Free Cash Flow Statement | J2: Cash Flow Monthly (Rs.) | K2: Cash Flow Annual (Rs.) | L2: %age of total business cash flow | N2: Expected Investment Potential- 5 Years
A3: Expense/s | E3: Revenue/s | H3: 1 | I3: Net Profit (Cash flow from business/service)- B/F (A) | J3: =B21 -> 0 | K3: =+J3*12 -> 0 | L3: =+K3/K3*100 -> #DIV/0! | N3: No. of Years | O3: Annual FCF (in Rs.) | P3: Haircut (%) | Q3: Net Annual FCF (In Rs.)
A4: Particulars | B4: Amt. (in Rs.) | C4: %age of total revenue | E4: Particulars | F4: Amt. (in Rs.) | I4: Less: Household Expenses | N4: Current Year- Computed 23-24 | O4: =+K17 -> -128400 | P4: NA | Q4: =+O4 -> -128400
A5: Purchase of consumables/raw material | C5: =+B5/F$5*100 -> #DIV/0! | E5: Business Sales/Service receipts/Rental Income/Commission | H5: 2 | I5: Ration/Meal Expenses of family (Milk, Grocery, Veggies etc.) | J5: 2500 | K5: =+J5*12 -> 30000 | L5: =+K5/K$3*100 -> #DIV/0! | N5: Previous Year-1 (22-23) | O5: =+Q4 -> -128400 | P5: 0.15 | Q5: =+O5-(O5*P5) -> -109140
A6: Labour/Staff Salaries | C6: =+B6/F$5*100 -> #DIV/0! | E6: Other Income (Direct business) | H6: 3 | I6: Kids School Fee + Admission Fee | J6: 2000 | K6: =+J6*12 -> 24000 | L6: =+K6/K$3*100 -> #DIV/0! | N6: Previous Year-2 (21-22) | O6: =+Q5 -> -109140 | P6: 0.3 | Q6: =+O6-(O6*P6) -> -76398
A7: Fuel i.e. Petrol/Diesel/Gas | C7: =+B7/F$5*100 -> #DIV/0! | H7: 4 | I7: Rental (others) | J7: 1500 | K7: =+J7*12 -> 18000 | L7: =+K7/K$3*100 -> #DIV/0! | N7: Previous Year-3 (20-21)- Post Covid effect | O7: =+Q6 -> -76398 | P7: 1 | Q7: =+O7-(O7*P7) -> 0
A8: Electricity Expenses | C8: =+B8/F$5*100 -> #DIV/0! | H8: 5 | I8: Electricity | J8: 800 | K8: =+J8*12 -> 9600 | L8: =+K8/K$3*100 -> #DIV/0! | N8: Previous Year-4 (19-20) | O8: =+Q6 -> -76398 | P8: 0.25 | Q8: =+O8-(O8*P8) -> -57298.5
A9: Loading/Unloading expenses | C9: =+B9/F$5*100 -> #DIV/0! | H9: 6 | I9: Medical expenses (general) | J9: 1200 | K9: =+J9*12 -> 14400 | L9: =+K9/K$3*100 -> #DIV/0! | N9: Previous Year-5 (18-19) | O9: =+Q6 -> -76398 | P9: 0.15 | Q9: =+O9-(O9*P9) -> -64938.3
A10: Rental/ Municipality payment | C10: =+B10/F$5*100 -> #DIV/0! | H10: 7 | I10: Insurance Premiums | J10: 1000 | K10: =+J10*12 -> 12000 | L10: =+K10/K$3*100 -> #DIV/0! | N10: Total Savings/Investment in last 5 yrs | O10: =+SUM(O5:O9) -> -466734 | Q10: =+SUM(Q5:Q9) -> -307774.8
A11: Commission Payment | C11: =+B11/F$5*100 -> #DIV/0! | H11: 8 | I11: Home Repair and Maintenance | J11: 200 | K11: =+J11*12 -> 2400 | L11: =+K11/K$3*100 -> #DIV/0!
A12: Other expenses (directly for bus. if any) | C12: =+B12/F$5*100 -> #DIV/0! | H12: 9 | I12: Vehicle Fuel, Repair and Maintenance | J12: 1000 | K12: =+J12*12 -> 12000 | L12: =+K12/K$3*100 -> #DIV/0! | N12: Mapping of major investment/deployment of savings in last 5 years (basis Net Annual FCF)
A13: Gross Margin/(Loss) | B13: =+F14-SUM(B5:B12) -> 0 | C13: =+B13/F$5*100 -> #DIV/0! | H13: 10 | I13: Mobile/Telehone expenses (Other family) | J13: 300 | K13: =+J13*12 -> 3600 | L13: =+K13/K$3*100 -> #DIV/0! | N13: Type of major investment/savings | P13: Amt. (in Rs.) | Q13: %age of total
A14: Total | B14: =+SUM(B5:B13) -> 0 | E14: Total | F14: =+SUM(F5:F10) -> 0 | H14: 11 | I14: Other Misc. household exp. | J14: 200 | K14: =+J14*12 -> 2400 | L14: =+K14/K$3*100 -> #DIV/0! | N14: Bank Balance/Cash in hand | P14: =+Q10*30% -> -92332.44 | Q14: =+P14/Q$10*100 -> 30
A15: Stationery | C15: =+B15/F$5*100 -> #DIV/0! | E15: Gross Profit/(Loss) (b/f) | F15: =+B13 -> 0 | I15: Total Household Expenses (B) | J15: =+SUM(J5:J14) -> 10700 | K15: =+SUM(K5:K14) -> 128400 | L15: =+SUM(L5:L14) -> #DIV/0! | N15: Purchase of machinery for office/vehicle purchase | Q15: =+P15/Q$10*100 -> 0
A16: Staff welfare | C16: =+B16/F$5*100 -> #DIV/0! | E16: FD/ Bank Saving Interest | N16: Plot Purchase/loan repayment/others etc. | Q16: =+P16/Q$10*100 -> 0
A17: Admin Expenses | C17: =+B17/F$5*100 -> #DIV/0! | E17: Other Income | I17: Net Free Cash Flow (A-B) | J17: =+J3-J15 -> -10700 | K17: =+K3-K15 -> -128400 | L17: =+L3-L15 -> #DIV/0! | N17: Total Savings/Investments | P17: =+SUM(P14:P16) -> -92332.44 | Q17: =+SUM(Q14:Q16) -> 30
A18: Reimbursement of expenses | C18: =+B18/F$5*100 -> #DIV/0!
A19: Interest & Bank Charges | C19: =+B19/F$5*100 -> #DIV/0!
A20: Other Misc. Exp. | C20: =+B20/F$5*100 -> #DIV/0!
A21: Net Margin/Profit or (Loss) | B21: =+F22-SUM(B15:B19) -> 0 | C21: =+B21/F$5*100 -> #DIV/0!
A22: Total | B22: =+SUM(B15:B21) -> 0 | E22: Total | F22: =+SUM(F15:F17) -> 0

Sheet Consolidated Fin
A1: Financial Sheet & Analysis
A2: Applicant Name | B2: Consolidated
A3: Particulars | B3: ='Fin -1'!B3 -> Audited | C3: ='Fin -1'!C3 -> Audited | D3: ='Fin -1'!D3 -> Audited | E3: YOY% Change
A4: PROFIT & LOSS ACCOUNT | B4: ='Fin -1'!B4 -> 45382 | C4: ='Fin -1'!C4 -> 45747 | D4: ='Fin -1'!D4 -> 46112 | E4: =C4 -> 45747 | F4: =D4 -> 46112
A5: Gross Receipts /turnover | B5: ='Fin -1'!B5+'Fin -2'!B5+'Fin -3'!B5+'Fin -4'!B5 -> 0 | C5: ='Fin -1'!C5+'Fin -2'!C5+'Fin -3'!C5+'Fin -4'!C5 -> 0 | D5: ='Fin -1'!D5+'Fin -2'!D5+'Fin -3'!D5+'Fin -4'!D5 -> 0 | E5: =IF(B5=0,"",(C5-B5)/B5) | F5: =IF(C5=0,"",(D5-C5)/C5)
A6: Other income ( incidental to business/Business income ) | B6: ='Fin -1'!B6+'Fin -2'!B6+'Fin -3'!B6+'Fin -4'!B6 -> 0 | C6: ='Fin -1'!C6+'Fin -2'!C6+'Fin -3'!C6+'Fin -4'!C6 -> 0 | D6: ='Fin -1'!D6+'Fin -2'!D6+'Fin -3'!D6+'Fin -4'!D6 -> 0 | E6: =IF(B6=0,"",(C6-B6)/B6) | F6: =IF(C6=0,"",(D6-C6)/C6)
A7: TOTAL OPERATING INCOME | B7: ='Fin -1'!B7+'Fin -2'!B7+'Fin -3'!B7+'Fin -4'!B7 -> 0 | C7: ='Fin -1'!C7+'Fin -2'!C7+'Fin -3'!C7+'Fin -4'!C7 -> 0 | D7: ='Fin -1'!D7+'Fin -2'!D7+'Fin -3'!D7+'Fin -4'!D7 -> 0 | E7: =IF(B7=0,"",(C7-B7)/B7) | F7: =IF(C7=0,"",(D7-C7)/C7)
A8: Other Non-Operating Income | B8: ='Fin -1'!B8+'Fin -2'!B8+'Fin -3'!B8+'Fin -4'!B8 -> 0 | C8: ='Fin -1'!C8+'Fin -2'!C8+'Fin -3'!C8+'Fin -4'!C8 -> 0 | D8: ='Fin -1'!D8+'Fin -2'!D8+'Fin -3'!D8+'Fin -4'!D8 -> 0 | E8: =IF(B8=0,"",(C8-B8)/B8) | F8: =IF(C8=0,"",(D8-C8)/C8)
A9: TOTAL NON OPERATING INCOME | B9: ='Fin -1'!B9+'Fin -2'!B9+'Fin -3'!B9+'Fin -4'!B9 -> 0 | C9: ='Fin -1'!C9+'Fin -2'!C9+'Fin -3'!C9+'Fin -4'!C9 -> 0 | D9: ='Fin -1'!D9+'Fin -2'!D9+'Fin -3'!D9+'Fin -4'!D9 -> 0 | E9: =IF(B9=0,"",(C9-B9)/B9) | F9: =IF(C9=0,"",(D9-C9)/C9)
A10: TOTAL INCOME | B10: ='Fin -1'!B10+'Fin -2'!B10+'Fin -3'!B10+'Fin -4'!B10 -> 0 | C10: ='Fin -1'!C10+'Fin -2'!C10+'Fin -3'!C10+'Fin -4'!C10 -> 0 | D10: ='Fin -1'!D10+'Fin -2'!D10+'Fin -3'!D10+'Fin -4'!D10 -> 0 | E10: =IF(B10=0,"",(C10-B10)/B10) | F10: =IF(C10=0,"",(D10-C10)/C10)
A11: Cost of Goods Sold | B11: ='Fin -1'!B11+'Fin -2'!B11+'Fin -3'!B11+'Fin -4'!B11 -> 0 | C11: ='Fin -1'!C11+'Fin -2'!C11+'Fin -3'!C11+'Fin -4'!C11 -> 0 | D11: ='Fin -1'!D11+'Fin -2'!D11+'Fin -3'!D11+'Fin -4'!D11 -> 0 | E11: =IF(B11=0,"",(C11-B11)/B11) | F11: =IF(C11=0,"",(D11-C11)/C11)
A12: Staff Salaries | B12: ='Fin -1'!B12+'Fin -2'!B12+'Fin -3'!B12+'Fin -4'!B12 -> 0 | C12: ='Fin -1'!C12+'Fin -2'!C12+'Fin -3'!C12+'Fin -4'!C12 -> 0 | D12: ='Fin -1'!D12+'Fin -2'!D12+'Fin -3'!D12+'Fin -4'!D12 -> 0 | E12: =IF(B12=0,"",(C12-B12)/B12) | F12: =IF(C12=0,"",(D12-C12)/C12)
A13: Rent Expenses | B13: ='Fin -1'!B13+'Fin -2'!B13+'Fin -3'!B13+'Fin -4'!B13 -> 0 | C13: ='Fin -1'!C13+'Fin -2'!C13+'Fin -3'!C13+'Fin -4'!C13 -> 0 | D13: ='Fin -1'!D13+'Fin -2'!D13+'Fin -3'!D13+'Fin -4'!D13 -> 0 | E13: =IF(B13=0,"",(C13-B13)/B13) | F13: =IF(C13=0,"",(D13-C13)/C13)
A14: Administrative Expenses | B14: ='Fin -1'!B14+'Fin -2'!B14+'Fin -3'!B14+'Fin -4'!B14 -> 0 | C14: ='Fin -1'!C14+'Fin -2'!C14+'Fin -3'!C14+'Fin -4'!C14 -> 0 | D14: ='Fin -1'!D14+'Fin -2'!D14+'Fin -3'!D14+'Fin -4'!D14 -> 0 | E14: =IF(B14=0,"",(C14-B14)/B14) | F14: =IF(C14=0,"",(D14-C14)/C14)
A15: Bank and Finance Charges | B15: ='Fin -1'!B15+'Fin -2'!B15+'Fin -3'!B15+'Fin -4'!B15 -> 0 | C15: ='Fin -1'!C15+'Fin -2'!C15+'Fin -3'!C15+'Fin -4'!C15 -> 0 | D15: ='Fin -1'!D15+'Fin -2'!D15+'Fin -3'!D15+'Fin -4'!D15 -> 0 | E15: =IF(B15=0,"",(C15-B15)/B15) | F15: =IF(C15=0,"",(D15-C15)/C15)
A16: Others | B16: ='Fin -1'!B16+'Fin -2'!B16+'Fin -3'!B16+'Fin -4'!B16 -> 0 | C16: ='Fin -1'!C16+'Fin -2'!C16+'Fin -3'!C16+'Fin -4'!C16 -> 0 | D16: ='Fin -1'!D16+'Fin -2'!D16+'Fin -3'!D16+'Fin -4'!D16 -> 0 | E16: =IF(B16=0,"",(C16-B16)/B16) | F16: =IF(C16=0,"",(D16-C16)/C16)
... A28: CASH PROFITS (Excluding Non Business Income) | B28: ='Fin -1'!B28+'Fin -2'!B28+'Fin -3'!B28+'Fin -4'!B28 -> 0 | C28: ='Fin -1'!C28+'Fin -2'!C28+'Fin -3'!C28+'Fin -4'!C28 -> 0 | D28: ='Fin -1'!D28+'Fin -2'!D28+'Fin -3'!D28+'Fin -4'!D28 -> 0 | E28: =IF(B28=0,"",(C28-B28)/B28) | F28: =IF(C28=0,"",(D28-C28)/C28)
E29: =IF(B29=0,"",(C29-B29)/B29)
A30: BALANCE SHEET | B30: =B4 -> 45382 | C30: =C4 -> 45747 | D30: =D4 -> 46112 | E30: YOY% Change
A31: LIABILITY | E31: =E4 -> 45747 | F31: =F4 -> 46112
A32: Corpus Fund/ Capital | B32: ='Fin -1'!B32+'Fin -2'!B32+'Fin -3'!B32+'Fin -4'!B32 -> 0 | C32: ='Fin -1'!C32+'Fin -2'!C32+'Fin -3'!C32+'Fin -4'!C32 -> 0 | D32: ='Fin -1'!D32+'Fin -2'!D32+'Fin -3'!D32+'Fin -4'!D32 -> 0 | E32: =IF(B32=0,"",(C32-B32)/B32) | F32: =IF(C32=0,"",(D32-C32)/C32)
A33: Excess of Income Over Expenditure | B33: ='Fin -1'!B33+'Fin -2'!B33+'Fin -3'!B33+'Fin -4'!B33 -> 0 | C33: ='Fin -1'!C33+'Fin -2'!C33+'Fin -3'!C33+'Fin -4'!C33 -> 0 | D33: ='Fin -1'!D33+'Fin -2'!D33+'Fin -3'!D33+'Fin -4'!D33 -> 0 | E33: =IF(B33=0,"",(C33-B33)/B33) | F33: =IF(C33=0,"",(D33-C33)/C33)
A34: Total Funds / Net Worth | B34: ='Fin -1'!B34+'Fin -2'!B34+'Fin -3'!B34+'Fin -4'!B34 -> 0 | C34: ='Fin -1'!C34+'Fin -2'!C34+'Fin -3'!C34+'Fin -4'!C34 -> 0 | D34: ='Fin -1'!D34+'Fin -2'!D34+'Fin -3'!D34+'Fin -4'!D34 -> 0 | E34: =IF(B34=0,"",(C34-B34)/B34) | F34: =IF(C34=0,"",(D34-C34)/C34)
A35: Unsecured loans from promoters (Considered Quasi Equity) | B35: ='Fin -1'!B35+'Fin -2'!B35+'Fin -3'!B35+'Fin -4'!B35 -> 0 | C35: ='Fin -1'!C35+'Fin -2'!C35+'Fin -3'!C35+'Fin -4'!C35 -> 0 | D35: ='Fin -1'!D35+'Fin -2'!D35+'Fin -3'!D35+'Fin -4'!D35 -> 0 | E35: =IF(B35=0,"",(C35-B35)/B35) | F35: =IF(C35=0,"",(D35-C35)/C35)
A36: Revised Net Worth | B36: ='Fin -1'!B36+'Fin -2'!B36+'Fin -3'!B36+'Fin -4'!B36 -> 0 | C36: ='Fin -1'!C36+'Fin -2'!C36+'Fin -3'!C36+'Fin -4'!C36 -> 0 | D36: ='Fin -1'!D36+'Fin -2'!D36+'Fin -3'!D36+'Fin -4'!D36 -> 0 | E36: =IF(B36=0,"",(C36-B36)/B36) | F36: =IF(C36=0,"",(D36-C36)/C36)
A37: Revaluation Reserves | B37: ='Fin -1'!B37+'Fin -2'!B37+'Fin -3'!B37+'Fin -4'!B37 -> 0 | C37: ='Fin -1'!C37+'Fin -2'!C37+'Fin -3'!C37+'Fin -4'!C37 -> 0 | D37: ='Fin -1'!D37+'Fin -2'!D37+'Fin -3'!D37+'Fin -4'!D37 -> 0 | E37: =IF(B37=0,"",(C37-B37)/B37) | F37: =IF(C37=0,"",(D37-C37)/C37)
A38: Adjusted Networth (ATNW) | B38: ='Fin -1'!B38+'Fin -2'!B38+'Fin -3'!B38+'Fin -4'!B38 -> 0 | C38: ='Fin -1'!C38+'Fin -2'!C38+'Fin -3'!C38+'Fin -4'!C38 -> 0 | D38: ='Fin -1'!D38+'Fin -2'!D38+'Fin -3'!D38+'Fin -4'!D38 -> 0 | E38: =IF(B38=0,"",(C38-B38)/B38) | F38: =IF(C38=0,"",(D38-C38)/C38)
A39: Secured Term Loans- Banks/FI | B39: ='Fin -1'!B39+'Fin -2'!B39+'Fin -3'!B39+'Fin -4'!B39 -> 0 | C39: ='Fin -1'!C39+'Fin -2'!C39+'Fin -3'!C39+'Fin -4'!C39 -> 0 | D39: ='Fin -1'!D39+'Fin -2'!D39+'Fin -3'!D39+'Fin -4'!D39 -> 0 | E39: =IF(B39=0,"",(C39-B39)/B39) | F39: =IF(C39=0,"",(D39-C39)/C39)
A40: Payable in next one year ( Installments due in next one year) | B40: ='Fin -1'!B40+'Fin -2'!B40+'Fin -3'!B40+'Fin -4'!B40 -> 0 | C40: ='Fin -1'!C40+'Fin -2'!C40+'Fin -3'!C40+'Fin -4'!C40 -> 0 | D40: ='Fin -1'!D40+'Fin -2'!D40+'Fin -3'!D40+'Fin -4'!D40 -> 0 | E40: =IF(B40=0,"",(C40-B40)/B40) | F40: =IF(C40=0,"",(D40-C40)/C40)
A41: Payable after one year | B41: ='Fin -1'!B41+'Fin -2'!B41+'Fin -3'!B41+'Fin -4'!B41 -> 0 | C41: ='Fin -1'!C41+'Fin -2'!C41+'Fin -3'!C41+'Fin -4'!C41 -> 0 | D41: ='Fin -1'!D41+'Fin -2'!D41+'Fin -3'!D41+'Fin -4'!D41 -> 0 | E41: =IF(B41=0,"",(C41-B41)/B41) | F41: =IF(C41=0,"",(D41-C41)/C41)
A42: Total Secured Loans - Banks/FI | B42: ='Fin -1'!B42+'Fin -2'!B42+'Fin -3'!B42+'Fin -4'!B42 -> 0 | C42: ='Fin -1'!C42+'Fin -2'!C42+'Fin -3'!C42+'Fin -4'!C42 -> 0 | D42: ='Fin -1'!D42+'Fin -2'!D42+'Fin -3'!D42+'Fin -4'!D42 -> 0 | E42: =IF(B42=0,"",(C42-B42)/B42) | F42: =IF(C42=0,"",(D42-C42)/C42)
A43: Bank CC/ OD | B43: ='Fin -1'!B43+'Fin -2'!B43+'Fin -3'!B43+'Fin -4'!B43 -> 0 | C43: ='Fin -1'!C43+'Fin -2'!C43+'Fin -3'!C43+'Fin -4'!C43 -> 0 | D43: ='Fin -1'!D43+'Fin -2'!D43+'Fin -3'!D43+'Fin -4'!D43 -> 0 | E43: =IF(B43=0,"",(C43-B43)/B43) | F43: =IF(C43=0,"",(D43-C43)/C43)
... A57: TOTAL LIABILITIES | B57: ='Fin -1'!B57+'Fin -2'!B57+'Fin -3'!B57+'Fin -4'!B57 -> 0 | C57: ='Fin -1'!C57+'Fin -2'!C57+'Fin -3'!C57+'Fin -4'!C57 -> 0 | D57: ='Fin -1'!D57+'Fin -2'!D57+'Fin -3'!D57+'Fin -4'!D57 -> 0 | E57: =IF(B57=0,"",(C57-B57)/B57) | F57: =IF(C57=0,"",(D57-C57)/C57)
A58: ASSETS | E58: =IF(B58=0,"",(C58-B58)/B58) | F58: =IF(C58=0,"",(D58-C58)/C58)
A59: Gross Block | B59: ='Fin -1'!B59+'Fin -2'!B59+'Fin -3'!B59+'Fin -4'!B59 -> 0 | C59: ='Fin -1'!C59+'Fin -2'!C59+'Fin -3'!C59+'Fin -4'!C59 -> 0 | D59: ='Fin -1'!D59+'Fin -2'!D59+'Fin -3'!D59+'Fin -4'!D59 -> 0 | E59: =IF(B59=0,"",(C59-B59)/B59) | F59: =IF(C59=0,"",(D59-C59)/C59)
A60: Accumulated Depreciation | B60: ='Fin -1'!B60+'Fin -2'!B60+'Fin -3'!B60+'Fin -4'!B60 -> 0 | C60: ='Fin -1'!C60+'Fin -2'!C60+'Fin -3'!C60+'Fin -4'!C60 -> 0 | D60: ='Fin -1'!D60+'Fin -2'!D60+'Fin -3'!D60+'Fin -4'!D60 -> 0 | E60: =IF(B60=0,"",(C60-B60)/B60) | F60: =IF(C60=0,"",(D60-C60)/C60)
A61: Net Fixed Assets | B61: ='Fin -1'!B61+'Fin -2'!B61+'Fin -3'!B61+'Fin -4'!B61 -> 0 | C61: ='Fin -1'!C61+'Fin -2'!C61+'Fin -3'!C61+'Fin -4'!C61 -> 0 | D61: ='Fin -1'!D61+'Fin -2'!D61+'Fin -3'!D61+'Fin -4'!D61 -> 0 | E61: =IF(B61=0,"",(C61-B61)/B61) | F61: =IF(C61=0,"",(D61-C61)/C61)
A62: Intangible Assets(Misc Exp, DRE,Prelim Exp, Acc Losses) | B62: ='Fin -1'!B62+'Fin -2'!B62+'Fin -3'!B62+'Fin -4'!B62 -> 0 | C62: ='Fin -1'!C62+'Fin -2'!C62+'Fin -3'!C62+'Fin -4'!C62 -> 0 | D62: ='Fin -1'!D62+'Fin -2'!D62+'Fin -3'!D62+'Fin -4'!D62 -> 0 | E62: =IF(B62=0,"",(C62-B62)/B62) | F62: =IF(C62=0,"",(D62-C62)/C62)
A63: Total Fixed Assets | B63: ='Fin -1'!B63+'Fin -2'!B63+'Fin -3'!B63+'Fin -4'!B63 -> 0 | C63: ='Fin -1'!C63+'Fin -2'!C63+'Fin -3'!C63+'Fin -4'!C63 -> 0 | D63: ='Fin -1'!D63+'Fin -2'!D63+'Fin -3'!D63+'Fin -4'!D63 -> 0 | E63: =IF(B63=0,"",(C63-B63)/B63) | F63: =IF(C63=0,"",(D63-C63)/C63)
A64: Current Assets | B64: ='Fin -1'!B64+'Fin -2'!B64+'Fin -3'!B64+'Fin -4'!B64 -> 0 | C64: ='Fin -1'!C64+'Fin -2'!C64+'Fin -3'!C64+'Fin -4'!C64 -> 0 | D64: ='Fin -1'!D64+'Fin -2'!D64+'Fin -3'!D64+'Fin -4'!D64 -> 0 | E64: =IF(B64=0,"",(C64-B64)/B64) | F64: =IF(C64=0,"",(D64-C64)/C64)
...

Sheet Fin -1
A1: Financial Sheet & Analysis
A2: Applicant Name
A3: Particulars | B3: Audited | C3: Audited | D3: Audited | E3: YOY% Change | G3: Comments on financials (If any)
A4: PROFIT & LOSS ACCOUNT | B4: 45382 | C4: 45747 | D4: 46112 | E4: =C4 -> 45747 | F4: =D4 -> 46112 | G4: Operating Income:- .
A5: Gross Receipts /turnover | E5: =IF(B5=0,"",(C5-B5)/B5) | F5: =IF(C5=0,"",(D5-C5)/C5)
A6: Other income ( incidental to business/Business income ) | E6: =IF(B6=0,"",(C6-B6)/B6) | F6: =IF(C6=0,"",(D6-C6)/C6)
A7: TOTAL OPERATING INCOME | B7: =B5+B6 -> 0 | C7: =C5+C6 -> 0 | D7: =D5+D6 -> 0 | E7: =IF(B7=0,"",(C7-B7)/B7) | F7: =IF(C7=0,"",(D7-C7)/C7)
A8: Other Non-Operating Income | D8: 0 | E8: =IF(B8=0,"",(C8-B8)/B8) | F8: =IF(C8=0,"",(D8-C8)/C8) | G8: Non Operative Income:
A9: TOTAL NON OPERATING INCOME | B9: =SUM(B8:B8) -> 0 | C9: =SUM(C8:C8) -> 0 | D9: =SUM(D8:D8) -> 0 | E9: =IF(B9=0,"",(C9-B9)/B9) | F9: =IF(C9=0,"",(D9-C9)/C9)
A10: TOTAL INCOME | B10: =B7+B9 -> 0 | C10: =C7+C9 -> 0 | D10: =D7+D9 -> 0 | E10: =IF(B10=0,"",(C10-B10)/B10) | F10: =IF(C10=0,"",(D10-C10)/C10)
A11: Cost of Goods Sold | E11: =IF(B11=0,"",(C11-B11)/B11) | F11: =IF(C11=0,"",(D11-C11)/C11)
A12: Staff Salaries | E12: =IF(B12=0,"",(C12-B12)/B12) | F12: =IF(C12=0,"",(D12-C12)/C12) | G12: Expense:-
A13: Rent Expenses | E13: =IF(B13=0,"",(C13-B13)/B13) | F13: =IF(C13=0,"",(D13-C13)/C13)
A14: Administrative Expenses | E14: =IF(B14=0,"",(C14-B14)/B14) | F14: =IF(C14=0,"",(D14-C14)/C14)
A15: Bank and Finance Charges | E15: =IF(B15=0,"",(C15-B15)/B15) | F15: =IF(C15=0,"",(D15-C15)/C15)
A16: Others | D16: 0 | E16: =IF(B16=0,"",(C16-B16)/B16) | F16: =IF(C16=0,"",(D16-C16)/C16)
A17: EBITDA | B17: =B7-SUM(B11:B16) -> 0 | C17: =C7-SUM(C11:C16) -> 0 | D17: =D7-SUM(D11:D16) -> 0 | E17: =IF(B17=0,"",(C17-B17)/B17) | F17: =IF(C17=0,"",(D17-C17)/C17)
A18: Interest On Working Capital Loans | D18: 0 | E18: =IF(B18=0,"",(C18-B18)/B18) | F18: =IF(C18=0,"",(D18-C18)/C18) | G18: Interest on Loans:-
A19: Interest to Bank / Financial Institutions (Term Loans) | D19: 0 | E19: =IF(B19=0,"",(C19-B19)/B19) | F19: =IF(C19=0,"",(D19-C19)/C19)
A20: Interest to related parties/partners/directors | D20: 0 | E20: =IF(B20=0,"",(C20-B20)/B20) | F20: =IF(C20=0,"",(D20-C20)/C20)
A21: Depreciation | E21: =IF(B21=0,"",(C21-B21)/B21) | F21: =IF(C21=0,"",(D21-C21)/C21)
A22: Remuneration to partners/directors | D22: 0 | E22: =IF(B22=0,"",(C22-B22)/B22) | F22: =IF(C22=0,"",(D22-C22)/C22)
A23: OPERATING PROFIT | B23: =B17-SUM(B18:B22) -> 0 | C23: =C17-SUM(C18:C22) -> 0 | D23: =D17-SUM(D18:D22) -> 0 | E23: =IF(B23=0,"",(C23-B23)/B23) | F23: =IF(C23=0,"",(D23-C23)/C23) | G23: PAT and Cash profit:
A24: PBT ( Incl Net of Non Operating Income/Exp) | B24: =B23+B9 -> 0 | C24: =C23+C9 -> 0 | D24: =D23+D9 -> 0 | E24: =IF(B24=0,"",(C24-B24)/B24) | F24: =IF(C24=0,"",(D24-C24)/C24)
A25: Tax | E25: =IF(B25=0,"",(C25-B25)/B25) | F25: =IF(C25=0,"",(D25-C25)/C25)
A26: PAT (as Per books) | B26: =B24-B25 -> 0 | C26: =C24-C25 -> 0 | D26: =D24-D25 -> 0 | E26: =IF(B26=0,"",(C26-B26)/B26) | F26: =IF(C26=0,"",(D26-C26)/C26)
A27: PAT (Excluding Non Business Income) | B27: =B23-B25 -> 0 | C27: =C23-C25 -> 0 | D27: =D23-D25 -> 0 | E27: =IF(B27=0,"",(C27-B27)/B27) | F27: =IF(C27=0,"",(D27-C27)/C27)
A28: CASH PROFITS (Excluding Non Business Income) | B28: =B27+B22+B21 -> 0 | C28: =C27+C22+C21 -> 0 | D28: =D27+D22+D21 -> 0 | E28: =IF(B28=0,"",(C28-B28)/B28) | F28: =IF(C28=0,"",(D28-C28)/C28)
E29: =IF(B29=0,"",(C29-B29)/B29)
A30: BALANCE SHEET | B30: =B4 -> 45382 | C30: =C4 -> 45747 | D30: =D4 -> 46112 | E30: YOY% Change
A31: LIABILITY | E31: =E4 -> 45747 | F31: =F4 -> 46112
A32: Corpus Fund/ Capital | E32: =IF(B32=0,"",(C32-B32)/B32) | F32: =IF(C32=0,"",(D32-C32)/C32) | G32: Net Worth/Corpus Fund:-
A33: Excess of Income Over Expenditure | E33: =IF(B33=0,"",(C33-B33)/B33) | F33: =IF(C33=0,"",(D33-C33)/C33)
A34: Total Funds / Net Worth | B34: =B32+B33 -> 0 | C34: =C32+C33 -> 0 | D34: =D32+D33 -> 0 | E34: =IF(B34=0,"",(C34-B34)/B34) | F34: =IF(C34=0,"",(D34-C34)/C34)
A35: Unsecured loans from promoters (Considered Quasi Equity) | D35: 0 | E35: =IF(B35=0,"",(C35-B35)/B35) | F35: =IF(C35=0,"",(D35-C35)/C35)
A36: Revised Net Worth | B36: =B34+B35 -> 0 | C36: =C34+C35 -> 0 | D36: =D34+D35 -> 0 | E36: =IF(B36=0,"",(C36-B36)/B36) | F36: =IF(C36=0,"",(D36-C36)/C36)
A37: Revaluation Reserves | B37: 0 | D37: 0 | E37: =IF(B37=0,"",(C37-B37)/B37) | F37: =IF(C37=0,"",(D37-C37)/C37)
A38: Adjusted Networth (ATNW) | B38: =B36-B74-B62 -> 0 | C38: =C36-C74-C62 -> 0 | D38: =D36-D74-D62 -> 0 | E38: =IF(B38=0,"",(C38-B38)/B38) | F38: =IF(C38=0,"",(D38-C38)/C38)
A39: Secured Term Loans- Banks/FI | D39: 0 | E39: =IF(B39=0,"",(C39-B39)/B39) | F39: =IF(C39=0,"",(D39-C39)/C39) | G39: Loans:-
A40: Payable in next one year ( Installments due in next one year) | D40: 0 | E40: =IF(B40=0,"",(C40-B40)/B40) | F40: =IF(C40=0,"",(D40-C40)/C40)
...

Sheet Fin -2
A1: Financial Sheet & Analysis
